Workbook

Sheet 選定提案書
B1: 福祉用具貸与選定提案書
B8: フリガナ | M8: =[1]受注票!R60 -> 0 | AQ8: 生年月日 | BJ8: 性別 | BN8: 担当者
B11: ご利用者様名 | M11: =[1]受注票!R62 -> 0 | AN11: 様 | AX11: 年 | BC11: 月 | BH11: 日
B17: 居宅支援事業所 | M17: =[1]受注票!H73 -> 0 | AV17: ケアマネジャー | BE17: =[1]受注票!AJ73 -> 0 | BW17: ｃｍ
B22: 【貸与を提案する福祉用具】
B24: No | D24: 種目名 | S24: 商品名 | AJ24: 提案する理由 | BQ24: 説明 | BW24: 採否
D27: 貸与価格
B30: 1 | S30: =[1]受注票!A20 -> 0 | BQ30: 実物 | BW30: 採
BQ32: カタログ
D34: =[1]受注票!AD20 -> 0 | BQ34: Web | BW34: 否
BQ36: 他
B38: 2 | S38: =[1]受注票!A22 -> 0 | BQ38: 実物 | BW38: 採
BQ40: カタログ
D42: =[1]受注票!AD22 -> 0 | BQ42: Web | BW42: 否
BQ44: 他
B46: 3 | S46: =[1]受注票!A24 -> 0 | BQ46: 実物 | BW46: 採
BQ48: カタログ
D50: =[1]受注票!AD24 -> 0 | BQ50: Web | BW50: 否
BQ52: 他
B54: 4 | S54: =[1]受注票!A26 -> 0 | BQ54: 実物 | BW54: 採
BQ56: カタログ
D58: =[1]受注票!AD26 -> 0 | BQ58: Web | BW58: 否
BQ60: 他
B62: 5 | S62: =[1]受注票!A28 -> 0 | BQ62: 実物 | BW62: 採
BQ64: カタログ
D66: =[1]受注票!AD28 -> 0 | BQ66: Web | BW66: 否
BQ68: 他
B70: 6 | S70: =[1]受注票!A30 -> 0 | BQ70: 実物 | BW70: 採
BQ72: カタログ
D74: =[1]受注票!AD30 -> 0 | BQ74: Web | BW74: 否
BQ76: 他
B78: 7 | S78: =[1]受注票!A32 -> 0 | BQ78: 実物 | BW78: 採
BQ80: カタログ
D82: =[1]受注票!AD32 -> 0 | BQ82: Web | BW82: 否
BQ84: 他
B86: 8 | S86: =[1]受注票!A34 -> 0 | BQ86: 実物 | BW86: 採
BQ88: カタログ
D90: =[1]受注票!AD34 -> 0 | BQ90: Web | BW90: 否
BQ92: 他
B94: 9 | S94: =[1]受注票!A36 -> 0 | BQ94: 実物 | BW94: 採
...
